Workbook
Name City: Sheet2!$B$2:$B$10
Name Day_Wise_Exursion: 'Day Wise Exursion'!$B$27:$B$37
Name Header: Sheet2!$H$12:$FH$12
Name MYName: IF(INDEX(Sheet2!$H$13:$FH$19,0,MATCH(Summary!XFD1,Header,0))=0,"",INDEX(Sheet2!$H$13:$FH$19,0,MATCH(Summary!XFD1,Header,0)))
Name Type: INDEX(Sheet2!$H$13:$FH$18,0,MATCH(Summary!$E11,Header,0))

Sheet Summary
D1: https://rateonclick.com/rate
H2: Address: - Shop No. 210, 2nd Floor, Pratap Complex, Metro Gate Number 3, near Munirka, Baba Gangnath Market, Munirka, New Delhi, Delhi 110067 Phone: +91-9870229792, +91-9910987264 Email: info@ghumofiroo.com
D6: Kerala Deluxe Plus Package
D7: =IF(AND(F17<>"", H17<>""), "For " & TEXT(LEFT(F17, FIND(" ", H17)-1), "00") & " Nights " & TEXT(LEFT(H17, FIND(" ", H17)-1), "00") & " Days", "") -> For 07 Nights 08 Days
D8: Travel Itinerary
D9: Welcome to Ghumo Firoo!
D11: This is Navin Kumar Mishra, and I will be working with you to plan your trip to Kerala.
D13: Please find below details for your trip and feel free to call me at +91-9910987264.
D15: Query Details
D16: #Booking Code | F16: Q/25/979949 | H16: Total Guests | K16: 2 | N16: Occupancy Type | O16: Double | P16: SIC Sightseeing | Q16: Honeymoon Inclusions
D17: Trip Duration | F17: =(H37-G37)&" "&"Nights" -> 7 Nights | H17: =DAY(H37-G37)+1&" "&"Days" -> 8 Days | J17: =O17 -> NA | K17: =IF(O16="Double", MOD(K16,2),IF(O16="Triple", MOD(K16,3),IF(O16="Quad", MOD(K16,4), 0))) -> 0 | N17: Passanger Type | O17: NA | P17: Activity 2
D18: Pick Up City | E18: Airport | F18: Drop City | H18: Airport | J18: Start Date | K18: =G37 -> 46178 | P18: Activity 3
D19: Destination Covered | F19: {=_xlfn.TEXTJOIN(", ", TRUE, _xlfn.UNIQUE(_xlfn._xlws.FILTER(D26:D36, D26:D36<>"")))} -> Kochi, Munnar, Thekkady , Varkala, Alleppey | J19: End Date | K19: =H37 -> 46185 | N19: Cab Type | O19: Sedan 4 Seater | P19: Activity 4
D20: Ghumo Firoo Travels: Where dreams become Itineraries, and Bucket-Lists turn into Checklists | P20: Activity 5
N21: Markup | O21: 0.04 | P21: Activity 6
N22: Cost of Markup | O22: =V37*O21 -> 2264 | P22: Activity 7
D24: Package Name: Kerala Deluxe Plus Package | O24: 1 Night/Day Price | T24: Total Price
D25: City | E25: Hotel Name | F25: Room Type | G25: Check-In | H25: Check-Out | I25: Nights | J25: Cab Type | K25: Meal Plan | L25: Rooms | M25: Total Guests | N25: Extra Passanger | O25: Double | P25: Triple | Q25: =IF(O17="NA", "Cost Not Applicable", "Cost of " & O17) -> Cost Not Applicable | R25: Transfer Cost | S25: Excursion Cost | T25: Total Room Price | U25: =IF(O17="NA", "Cost Not Applicable", "Total Cost of " & O17) -> Cost Not Applicable | V25: Total Price | W25: Advance | X25: Balance
A26: =IF(E26="","",E26&"-"&F26&"-"&$O$16&" "&$K26) -> Broad Bean Hotel-Standard Room-Double MAP | B26: =IF(E26="","",E26&"-"&$O$17&"-"&$O$16&" "&$K26) -> Broad Bean Hotel-NA-Double MAP | D26: Kochi | E26: Broad Bean Hotel | F26: Standard Room | G26: =IF(ISNUMBER($G$37), $G$37, "") -> 46178 | H26: =IF(I26=0, "", G26 + I26) -> 46179 | I26: 1 | J26: =IF(E26="","",$O$19) -> Sedan 4 Seater | K26: MAP | L26: =IF(E26="","",IF($O$16="Double", FLOOR($K$16/2, 1), IF($O$16="Triple", FLOOR($K$16/3, 1), 0))) -> 1 | M26: =IF(E26="","",$K$16) -> 2 | N26: =IF(E26="","",$K$17) -> 0 | O26: =IFERROR(IF(E26="","",IF($O$16="Double",VLOOKUP($A26,Price[],2,0),"")),0) -> 4300 | P26: =IFERROR(IF(E26="","",IF($O$16="Triple",VLOOKUP($A26,Price[],2,0),"")),0) | Q26: =IFERROR(IF(E26="","",VLOOKUP($B26,Extra_fare_price[#All],2,0)),0) -> 0 | R26: =IF(OR($O$19="",D26="",I26=""),"",I26 *IF(AND($E$18<>"",$H$18<>""),IF($E$18=$H$18,VLOOKUP($O$19, Price!$J:$L, MATCH(TRIM($E$18), Price!$J$1:$L$1, 0), FALSE),""),IF($E$18<>"",VLOOKUP($O$19, Price!$J:$L, MATCH(TRIM($E$18), Price!$J$1:$L$1, 0), FALSE),IF($H$18<>"",VLOOKUP($O$19, Price!$J:$L, MATCH(TRIM($H$18), Price!$J$1:$L$1, 0), FALSE),"")))) -> 3200 | S26: =IF(Q16="", "", _xlfn.XLOOKUP(Q16, ActivitiesMaster!C:C, ActivitiesMaster!E:E, 0) * $K$16) -> 0 | T26: =IF(E26="","",SUM(O26:P26)*I26*L26) -> 4300 | U26: =IF(E26="","",Q26*I26) -> 0 | V26: =IF(AND(R26="",T26="", U26=""), "", SUM(R26:U26)) -> 7500 | W26: 2000 | X26: =IF(V26="","",V26-W26) -> 5500 | Y26: =IF(V26 = (R26 + S26+T26 + U26), "✅", "❌") -> ✅ | Z26: 3000 | AA26: 18500 | AB26: 999 | AC26: 999 | AD26: =Z26-AB26 -> 2001 | AE26: =AA26-AC26 -> 17501
A27: =IF(E27="","",E27&"-"&F27&"-"&$O$16&" "&$K27) -> Blossom Hill Resort-Valley View Cottage (With Balcony)-Double MAP | B27: =IF(E27="","",E27&"-"&$O$17&"-"&$O$16&" "&$K27) -> Blossom Hill Resort-NA-Double MAP | D27: Munnar | E27: Blossom Hill Resort | F27: Valley View Cottage (With Balcony) | G27: =IF(E27="","",IF(ISNUMBER(H26), H26, "")) -> 46179 | H27: =IF(I27=0, "", G27 + I27) -> 46181 | I27: 2 | J27: =IF(E27="","",$O$19) -> Sedan 4 Seater | K27: MAP | L27: =IF(E27="","",IF($O$16="Double", FLOOR($K$16/2, 1), IF($O$16="Triple", FLOOR($K$16/3, 1), 0))) -> 1 | M27: =IF(E27="","",$K$16) -> 2 | N27: =IF(E27="","",$K$17) -> 0 | O27: =IFERROR(IF(E27="","",IF($O$16="Double",VLOOKUP($A27,Price[],2,0),"")),0) -> 4700 | P27: =IFERROR(IF(E27="","",IF($O$16="Triple",VLOOKUP($A27,Price[],2,0),"")),0) | Q27: =IFERROR(IF(E27="","",VLOOKUP($B27,Extra_fare_price[#All],2,0)),0) -> 0 | R27: =IF(OR($O$19="",D27="",I27=""),"",I27 *IF(AND($E$18<>"",$H$18<>""),IF($E$18=$H$18,VLOOKUP($O$19, Price!$J:$L, MATCH(TRIM($E$18), Price!$J$1:$L$1, 0), FALSE),""),IF($E$18<>"",VLOOKUP($O$19, Price!$J:$L, MATCH(TRIM($E$18), Price!$J$1:$L$1, 0), FALSE),IF($H$18<>"",VLOOKUP($O$19, Price!$J:$L, MATCH(TRIM($H$18), Price!$J$1:$L$1, 0), FALSE),"")))) -> 6400 | S27: =IF(Q17="", "", _xlfn.XLOOKUP(Q17, ActivitiesMaster!C:C, ActivitiesMaster!E:E, 0) * $K$16) | T27: =IF(E27="","",SUM(O27:P27)*I27*L27) -> 9400 | U27: =IF(E27="","",Q27*I27) -> 0 | V27: =IF(AND(R27="",T27="", U27=""), "", SUM(R27:U27)) -> 15800 | W27: 5000 | X27: =IF(V27="","",V27-W27) -> 10800 | Y27: =IF(V27 = (R27 + S27+T27 + U27), "✅", "❌") -> #VALUE! | Z27: 3000 | AB27: 999 | AD27: =Z27-AB27 -> 2001
A28: =IF(E28="","",E28&"-"&F28&"-"&$O$16&" "&$K28) -> Jungle Park Resort-Jungle View Venus (A/c)-Double MAP | B28: =IF(E28="","",E28&"-"&$O$17&"-"&$O$16&" "&$K28) -> Jungle Park Resort-NA-Double MAP | D28: Thekkady | E28: Jungle Park Resort | F28: Jungle View Venus (A/c) | G28: =IF(E28="","",IF(ISNUMBER(H27), H27, "")) -> 46181 | H28: =IF(I28=0, "", G28 + I28) -> 46182 | I28: 1 | J28: =IF(E28="","",$O$19) -> Sedan 4 Seater | K28: MAP | L28: =IF(E28="","",IF($O$16="Double", FLOOR($K$16/2, 1), IF($O$16="Triple", FLOOR($K$16/3, 1), 0))) -> 1 | M28: =IF(E28="","",$K$16) -> 2 | N28: =IF(E28="","",$K$17) -> 0 | O28: =IFERROR(IF(E28="","",IF($O$16="Double",VLOOKUP($A28,Price[],2,0),"")),0) -> 4900 | P28: =IFERROR(IF(E28="","",IF($O$16="Triple",VLOOKUP($A28,Price[],2,0),"")),0) | Q28: =IFERROR(IF(E28="","",VLOOKUP($B28,Extra_fare_price[#All],2,0)),0) -> 0 | R28: =IF(OR($O$19="",D28="",I28=""),"",I28 *IF(AND($E$18<>"",$H$18<>""),IF($E$18=$H$18,VLOOKUP($O$19, Price!$J:$L, MATCH(TRIM($E$18), Price!$J$1:$L$1, 0), FALSE),""),IF($E$18<>"",VLOOKUP($O$19, Price!$J:$L, MATCH(TRIM($E$18), Price!$J$1:$L$1, 0), FALSE),IF($H$18<>"",VLOOKUP($O$19, Price!$J:$L, MATCH(TRIM($H$18), Price!$J$1:$L$1, 0), FALSE),"")))) -> 3200 | S28: =IF(Q18="", "", _xlfn.XLOOKUP(Q18, ActivitiesMaster!C:C, ActivitiesMaster!E:E, 0) * $K$16) | T28: =IF(E28="","",SUM(O28:P28)*I28*L28) -> 4900 | U28: =IF(E28="","",Q28*I28) -> 0 | V28: =IF(AND(R28="",T28="", U28=""), "", SUM(R28:U28)) -> 8100 | W28: 9000 | X28: =IF(V28="","",V28-W28) -> -900 | Y28: =IF(V28 = (R28 + S28+T28 + U28), "✅", "❌") -> #VALUE! | Z28: 8500 | AB28: 999 | AD28: =Z28-AB28 -> 7501
A29: =IF(E29="","",E29&"-"&F29&"-"&$O$16&" "&$K29) -> Sunview Beach Resort & Spa by Citrine-Garden View-Double CP | B29: =IF(E29="","",E29&"-"&$O$17&"-"&$O$16&" "&$K29) -> Sunview Beach Resort & Spa by Citrine-NA-Double CP | D29: Varkala | E29: Sunview Beach Resort & Spa by Citrine | F29: Garden View | G29: =IF(E29="","",IF(ISNUMBER(H28), H28, "")) -> 46182 | H29: =IF(I29=0, "", G29 + I29) -> 46183 | I29: 1 | J29: =IF(E29="","",$O$19) -> Sedan 4 Seater | K29: CP | L29: =IF(E29="","",IF($O$16="Double", FLOOR($K$16/2, 1), IF($O$16="Triple", FLOOR($K$16/3, 1), 0))) -> 1 | M29: =IF(E29="","",$K$16) -> 2 | N29: =IF(E29="","",$K$17) -> 0 | O29: =IFERROR(IF(E29="","",IF($O$16="Double",VLOOKUP($A29,Price[],2,0),"")),0) -> 6500 | P29: =IFERROR(IF(E29="","",IF($O$16="Triple",VLOOKUP($A29,Price[],2,0),"")),0) | Q29: =IFERROR(IF(E29="","",VLOOKUP($B29,Extra_fare_price[#All],2,0)),0) -> 0 | R29: =IFERROR(IF(E29="","",VLOOKUP($O$19,Table2[],2,0)),0) -> 3200 | S29: =IF(Q19="", "", _xlfn.XLOOKUP(Q19, ActivitiesMaster!C:C, ActivitiesMaster!E:E, 0) * $K$16) | T29: =IF(E29="","",SUM(O29:P29)*I29*L29) -> 6500 | U29: =IF(E29="","",Q29*I29) -> 0 | V29: =IF(AND(R29="",T29="", U29=""), "", SUM(R29:U29)) -> 9700 | X29: =IF(V29="","",V29-W29) -> 9700 | Y29: =IF(V29 = (R29 + S29+T29 + U29), "✅", "❌") -> #VALUE! | Z29: 4000 | AB29: 999 | AD29: =Z29-AB29 -> 3001
A30: =IF(E30="","",E30&"-"&F30&"-"&$O$16&" "&$K30) -> Trium Resort & Houseboats-Standard Room Non AC-Double MAP | B30: =IF(E30="","",E30&"-"&$O$17&"-"&$O$16&" "&$K30) -> Trium Resort & Houseboats-NA-Double MAP | D30: Alleppey | E30: Trium Resort & Houseboats | F30: Standard Room Non AC | G30: =IF(E30="","",IF(ISNUMBER(H29), H29, "")) -> 46183 | H30: =IF(I30=0, "", G30 + I30) -> 46184 | I30: 1 | J30: =IF(E30="","",$O$19) -> Sedan 4 Seater | K30: MAP | L30: =IF(E30="","",IF($O$16="Double", FLOOR($K$16/2, 1), IF($O$16="Triple", FLOOR($K$16/3, 1), 0))) -> 1 | M30: =IF(E30="","",$K$16) -> 2 | N30: =IF(E30="","",$K$17) -> 0 | O30: =IFERROR(IF(E30="","",IF($O$16="Double",VLOOKUP($A30,Price[],2,0),"")),0) -> 2900 | P30: =IFERROR(IF(E30="","",IF($O$16="Triple",VLOOKUP($A30,Price[],2,0),"")),0) | Q30: =IFERROR(IF(E30="","",VLOOKUP($B30,Extra_fare_price[#All],2,0)),0) -> 0 | R30: =IFERROR(IF(E30="","",VLOOKUP($O$19,Table2[],2,0)),0) -> 3200 | S30: =IF(Q20="", "", _xlfn.XLOOKUP(Q20, ActivitiesMaster!C:C, ActivitiesMaster!E:E, 0) * $K$16) | T30: =IF(E30="","",SUM(O30:P30)*I30*L30) -> 2900 | U30: =IF(E30="","",Q30*I30) -> 0 | V30: =IF(AND(R30="",T30="", U30=""), "", SUM(R30:U30)) -> 6100 | W30: =IF(E30="","",Q30*I30) -> 0 | X30: =IF(V30="","",V30-W30) -> 6100 | Y30: =IF(V30 = (R30 + S30+T30 + U30), "✅", "❌") -> #VALUE! | Z30: 4000 | AB30: 999 | AD30: =Z30-AB30 -> 3001
A31: =IF(E31="","",E31&"-"&F31&"-"&$O$16&" "&$K31) -> Symphony Houseboats-A Day Cruise without room Checkin 1pm to Checkout 5:30pm same day ,Veg-Double CP | B31: =IF(E31="","",E31&"-"&$O$17&"-"&$O$16&" "&$K31) -> Symphony Houseboats-NA-Double CP | D31: Alleppey | E31: Symphony Houseboats | F31: A Day Cruise without room Checkin 1pm to Checkout 5:30pm same day ,Veg | G31: =IF(E31="","",IF(ISNUMBER(H30), H30, "")) -> 46184 | H31: =IF(I31=0, "", G31 + I31) -> 46185 | I31: 1 | J31: =IF(E31="","",$O$19) -> Sedan 4 Seater | K31: CP | L31: =IF(E31="","",IF($O$16="Double", FLOOR($K$16/2, 1), IF($O$16="Triple", FLOOR($K$16/3, 1), 0))) -> 1 | M31: =IF(E31="","",$K$16) -> 2 | N31: =IF(E31="","",$K$17) -> 0 | O31: =IFERROR(IF(E31="","",IF($O$16="Double",VLOOKUP($A31,Price[],2,0),"")),0) -> 3000 | P31: =IFERROR(IF(E31="","",IF($O$16="Triple",VLOOKUP($A31,Price[],2,0),"")),0) | Q31: =IFERROR(IF(E31="","",VLOOKUP($B31,Extra_fare_price[#All],2,0)),0) -> 0 | R31: =IFERROR(IF(E31="","",VLOOKUP($O$19,Table2[],2,0)),0) -> 3200 | S31: =IF(Q21="", "", _xlfn.XLOOKUP(Q21, ActivitiesMaster!C:C, ActivitiesMaster!E:E, 0) * $K$16) | T31: =IF(E31="","",SUM(O31:P31)*I31*L31) -> 3000 | U31: =IF(E31="","",Q31*I31) -> 0 | V31: =IF(AND(R31="",T31="", U31=""), "", SUM(R31:U31)) -> 6200 | W31: =IF(E31="","",Q31*I31) -> 0 | X31: =IF(V31="","",V31-W31) -> 6200 | Y31: =IF(V31 = (R31 + S31+T31 + U31), "✅", "❌") -> #VALUE!
A32: =IF(E32="","",E32&"-"&F32&"-"&$O$16&" "&$K32) | B32: =IF(E32="","",E32&"-"&$O$17&"-"&$O$16&" "&$K32) | G32: =IF(E32="","",IF(ISNUMBER(H31), H31, "")) | H32: =IF(I32=0, "", G32 + I32) | J32: =IF(E32="","",$O$19) | L32: =IF(E32="","",IF($O$16="Double", FLOOR($K$16/2, 1), IF($O$16="Triple", FLOOR($K$16/3, 1), 0))) | M32: =IF(E32="","",$K$16) | N32: =IF(E32="","",$K$17) | O32: =IFERROR(IF(E32="","",IF($O$16="Double",VLOOKUP($A32,Price[],2,0),"")),0) | P32: =IFERROR(IF(E32="","",IF($O$16="Triple",VLOOKUP($A32,Price[],2,0),"")),0) | Q32: =IFERROR(IF(E32="","",VLOOKUP($B32,Extra_fare_price[#All],2,0)),0) | R32: =IFERROR(IF(E32="","",VLOOKUP($O$19,Table2[],2,0)),0) | S32: =IF(Q22="", "", _xlfn.XLOOKUP(Q22, ActivitiesMaster!C:C, ActivitiesMaster!E:E, 0) * $K$16) | T32: =IF(E32="","",SUM(O32:P32)*I32*L32) | U32: =IF(E32="","",Q32*I32) | V32: =IF(AND(R32="",T32="", U32=""), "", SUM(R32:U32)) | W32: =IF(E32="","",Q32*I32) | X32: =IF(V32="","",V32-W32) | Y32: =IF(V32 = (R32 + S32+T32 + U32), "✅", "❌") -> #VALUE!
A33: =IF(E33="","",E33&"-"&F33&"-"&$O$16&" "&$K33) | B33: =IF(E33="","",E33&"-"&$O$17&"-"&$O$16&" "&$K33) | G33: =IF(E33="","",IF(ISNUMBER(H32), H32, "")) | H33: =IF(I33=0, "", G33 + I33) | J33: =IF(E33="","",$O$19) | L33: =IF(E33="","",IF($O$16="Double", FLOOR($K$16/2, 1), IF($O$16="Triple", FLOOR($K$16/3, 1), 0))) | M33: =IF(E33="","",$K$16) | N33: =IF(E33="","",$K$17) | O33: =IFERROR(IF(E33="","",IF($O$16="Double",VLOOKUP($A33,Price[],2,0),"")),0) | P33: =IFERROR(IF(E33="","",IF($O$16="Triple",VLOOKUP($A33,Price[],2,0),"")),0) | Q33: =IFERROR(IF(E33="","",VLOOKUP($B33,Extra_fare_price[#All],2,0)),0) | R33: =IFERROR(IF(E33="","",VLOOKUP($O$19,Table2[],2,0)),0) | T33: =IF(E33="","",SUM(O33:P33)*I33*L33) | U33: =IF(E33="","",Q33*I33) | V33: =IF(AND(R33="",T33="", U33=""), "", SUM(R33:U33)) | W33: =IF(E33="","",Q33*I33) | X33: =IF(V33="","",V33-W33) | Y33: =IF(V33 = (R33 + S33+T33 + U33), "✅", "❌") -> #VALUE!
A34: =IF(E34="","",E34&"-"&F34&"-"&$O$16&" "&$K34) | B34: =IF(E34="","",E34&"-"&$O$17&"-"&$O$16&" "&$K34) | G34: =IF(E34="","",IF(ISNUMBER(H33), H33, "")) | H34: =IF(I34=0, "", G34 + I34) | J34: =IF(E34="","",$O$19) | L34: =IF(E34="","",IF($O$16="Double", FLOOR($K$16/2, 1), IF($O$16="Triple", FLOOR($K$16/3, 1), 0))) | M34: =IF(E34="","",$K$16) | N34: =IF(E34="","",$K$17) | O34: =IFERROR(IF(E34="","",IF($O$16="Double",VLOOKUP($A34,Price[],2,0),"")),0) | P34: =IFERROR(IF(E34="","",IF($O$16="Triple",VLOOKUP($A34,Price[],2,0),"")),0) | Q34: =IFERROR(IF(E34="","",VLOOKUP($B34,Extra_fare_price[#All],2,0)),0) | R34: =IFERROR(IF(E34="","",VLOOKUP($O$19,Table2[],2,0)),0) | T34: =IF(E34="","",SUM(O34:P34)*I34*L34) | U34: =IF(E34="","",Q34*I34) | V34: =IF(AND(R34="",T34="", U34=""), "", SUM(R34:U34)) | W34: =IF(E34="","",Q34*I34) | X34: =IF(V34="","",V34-W34) | Y34: =IF(V34 = (R34 + S34+T34 + U34), "✅", "❌") -> #VALUE!
A35: =IF(E35="","",E35&"-"&F35&"-"&$O$16&" "&$K35) | B35: =IF(E35="","",E35&"-"&$O$17&"-"&$O$16&" "&$K35) | G35: =IF(E35="","",IF(ISNUMBER(H34), H34, "")) | I35: =IF(E35="","",DAY(H35-G35)) | J35: =IF(E35="","",$O$19) | L35: =IF(E35="","",IF($O$16="Double", FLOOR($K$16/2, 1), IF($O$16="Triple", FLOOR($K$16/3, 1), 0))) | M35: =IF(E35="","",$K$16) | N35: =IF(E35="","",$K$17) | O35: =IFERROR(IF(E35="","",IF($O$16="Double",VLOOKUP($A35,Price[],2,0),"")),0) | P35: =IFERROR(IF(E35="","",IF($O$16="Triple",VLOOKUP($A35,Price[],2,0),"")),0) | Q35: =IFERROR(IF(E35="","",VLOOKUP($B35,Extra_fare_price[#All],2,0)),0) | R35: =IFERROR(IF(E35="","",VLOOKUP($O$19,Table2[],2,0)),0) | T35: =IF(E35="","",SUM(O35:P35)*I35*L35) | U35: =IF(E35="","",Q35*I35) | V35: =IF(AND(R35="",T35="", U35=""), "", SUM(R35:U35)) | W35: =IF(E35="","",Q35*I35) | X35: =IF(V35="","",V35-W35) | Y35: =IF(V35 = (R35 + S35+T35 + U35), "✅", "❌") -> #VALUE!
A36: =IF(E36="","",E36&"-"&F36&"-"&$O$16&" "&$K36) | B36: =IF(E36="","",E36&"-"&$O$17&"-"&$O$16&" "&$K36) | G36: =IF(E36="","",IF(ISNUMBER(H35), H35, "")) | I36: =IF(E36="","",DAY(H36-G36)) | J36: =IF(E36="","",$O$19) | L36: =IF(E36="","",IF($O$16="Double", FLOOR($K$16/2, 1), IF($O$16="Triple", FLOOR($K$16/3, 1), 0))) | M36: =IF(E36="","",$K$16) | N36: =IF(E36="","",$K$17) | O36: =IFERROR(IF(E36="","",IF($O$16="Double",VLOOKUP($A36,Price[],2,0),"")),0) | P36: =IFERROR(IF(E36="","",IF($O$16="Triple",VLOOKUP($A36,Price[],2,0),"")),0) | Q36: =IFERROR(IF(E36="","",VLOOKUP($B36,Extra_fare_price[#All],2,0)),0) | R36: =IFERROR(IF(E36="","",VLOOKUP($O$19,Table2[],2,0)),0) | V36: =IF(AND(R36="",T36="", U36=""), "", SUM(R36:U36)) | X36: =IF(V36="","",V36-W36) | Y36: =IF(V36 = (R36 + S36+T36 + U36), "✅", "❌") -> #VALUE!
D37: Total Duration of Stay | G37: 46178 | H37: =IF(AND(ISNUMBER(G37), ISNUMBER(I37)), G37 + I37, "") -> 46185 | I37: =SUM(I26:I36) -> 7 | O37: =SUM(O26:O36) -> 26300 | P37: =SUM(P26:P36) -> 0 | Q37: =SUM(Q26:Q36) -> 0 | R37: =SUM(R26:R36)+IF(OR($O$19="",R26=""),"",VLOOKUP($O$19,Price!$J:$L,MATCH(TRIM($E$18),Price!$J$1:$L$1,0),FALSE)) -> 25600 | S37: =SUM(S26:S36) -> 0 | T37: =SUM(T26:T36) -> 31000 | U37: =SUM(U26:U36) -> 0 | V37: =SUM(R37:U37) -> 56600 | W37: =SUM(W26:W36) -> 16000 | X37: =SUM(X26:X36) -> 37400 | Y37: =IF(V37 = (R37 +S37+ T37 + U37), "✅", "❌") -> ✅
N38: Total Cost | R38: =SUM(R37:U37) -> 56600 | U38: =IF(V37 = (R37 + S37+T37 + U37), "✅", "❌") -> ✅
D39: Package Price Details
D40: Pax Type | F40: Total Guest | H40: Cost Per Guest Per Night | K40: Grand Total Cost | N40: Total Cost
D41: Total Adult or Child | F41: =K16-K17 -> 2 | H41: =(K41/F41)/$I$37 -> 4204.5714 | K41: =(N41*$O$21)+N41 -> 58864 | N41: =(R37/$F$43)*F41+T37 -> 56600
D42: Cost of Extra Adult Passenger/Child | F42: =$K$17 -> 0 | H42: =IF(F42=0, 0, K42/F42/$I$37) -> 0 | K42: =(N42*$O$21)+N42 -> 0 | N42: =(R37/$F$43)*F42+U37 -> 0
D43: Final Package Amount | F43: =SUM(F41:F42) -> 2 | H43: =K43/(F43*$I$37) -> 4204.5714 | K43: =K41+K42 -> 58864 | N43: =N41+N42 -> 56600
D44: Per Passenger Cost | H44: =K43/F43 -> 29432 | N44: =K43-N43 -> 2264
D45: IMPORTANT PACKAGES INFORMATION
D46: Packages Inclusion | H46: Packages Exclusion
D47: =IF(I37<>"","1. " & TEXT(I37,"00") & " nights’ stay at the hotels specified in the itinerary.","") -> 1. 07 nights’ stay at the hotels specified in the itinerary. | H47: 1. Extra Meals, Drinks & things not mentioned in including.
...

Sheet Raw
B2: Destination | C2: Hotel Code | D2: Hotel / Resort Name | E2: Room Type | F2: Double EP | G2: Double CP | H2: Double MAP | I2: Double AP | J2: Triple EP | K2: Triple CP | L2: Triple MAP | M2: Triple AP
B3: Alleppey | C3: KL1 | D3: Venice Iva Residency | E3: Deluxe Room | G3: 3900 | H3: 5100
B4: Thekkady | C4: KL2 | D4: The Elephant Court | E4: Patio | G4: 7200 | H4: 9100 | I4: 13500
B5: Thekkady | C5: KL3 | D5: The Elephant Court | E5: Honeymoon Suite | G5: 9500 | H5: 11400 | I5: 15800
B6: Thekkady | C6: KL4 | D6: The Elephant Court | E6: Garden Suite | G6: 12000 | H6: 13900 | I6: 18300
B7: Thekkady | C7: KL5 | D7: The Elephant Court | E7: Pool Studio | G7: 14500 | H7: 16400 | I7: 20800
B8: Thekkady | C8: KL6 | D8: The Elephant Court | E8: Extra Adult passenger | G8: 2000 | H8: 2950 | I8: 3950
B9: Thekkady | C9: KL7 | D9: The Elephant Court | E9: Child with bed | G9: 1250 | H9: 1700 | I9: 2150
B10: Thekkady | C10: KL8 | D10: The Elephant Court | E10: Child without bed | G10: 700 | H10: 1150 | I10: 1600
B11: Thekkady | C11: KL9 | D11: Peppervine | E11: Deluxe Room | G11: 4300 | H11: 5700 | I11: 7100
B12: Thekkady | C12: KL10 | D12: Peppervine | E12: Suite Room | G12: 5300 | H12: 6700 | I12: 8100
B13: Thekkady | C13: KL11 | D13: Peppervine | E13: Extra Adult passenger | G13: 1500 | H13: 2200 | I13: 2900
B14: Thekkady | C14: KL12 | D14: Peppervine | E14: Child with bed | G14: 950 | H14: 1300 | I14: 1650
B15: Thekkady | C15: KL13 | D15: Peppervine | E15: Child without bed | G15: 500 | H15: 850 | I15: 1200
... B53: Munnar | C53: KL53 | D53: Tea castle resort | E53: Child without bed | G53: 700 | H53: 1200 | I53: 1700
B54: Munnar | C54: KL54 | D54: The Breeze Resort | E54: Deluxe Room (With Balcony) | G54: 3500 | H54: 3400
B55: Munnar | C55: KL55 | D55: The Breeze Resort | E55: Extra Adult passenger | G55: 800 | H55: 1350
B56: Munnar | C56: KL56 | D56: The Whispering Meadows | E56: Executive Room | G56: 3600 | H56: 4900
B57: Munnar | C57: KL57 | D57: The Whispering Meadows | E57: Extra Adult passenger | G57: 800 | H57: 1450
B58: Munnar | C58: KL58 | D58: Blossom Hill Resort | E58: Valley View Cottage (With Balcony) | G58: 3400 | H58: =RAW[[#This Row],[Double CP]]+1300 -> 4700
B59: Munnar | C59: KL59 | D59: Blossom Hill Resort | E59: Extra Adult passenger | G59: 800 | H59: =RAW[[#This Row],[Double CP]]+650 -> 1450
B60: Alleppey | C60: KL62 | D60: Venice Iva Residency | E60: Quadruple Bed Room (04 pax) | G60: 4900 | H60: 6100
B61: Alleppey | C61: KL63 | D61: Venice Iva Residency | E61: Extra Adult passenger | G61: 800 | H61: 1400
B62: Munnar | C62: KL64 | D62: Seven Springs Plantation Resort | E62: Deluxe Room | G62: 3500 | H62: 4500
B63: Munnar | C63: KL65 | D63: Seven Springs Plantation Resort | E63: Super Deluxe Room | G63: 4500 | H63: 5500
B64: Munnar | C64: KL66 | D64: Seven Springs Plantation Resort | E64: Suite Rooms | G64: 5500 | H64: 6500
B65: Munnar | C65: KL67 | D65: Seven Springs Plantation Resort | E65: Tree House | G65: 8000 | H65: 9000
B66: Munnar | C66: KL68 | D66: Seven Springs Plantation Resort | E66: Extra Adult passenger | G66: 1000 | H66: 2000
B67: Alleppey | C67: KL69 | D67: Casino Houseboats | E67: Standard | I67: 5500
B68: Alleppey | C68: KL70 | D68: Casino Houseboats | E68: Preimum | I68: 8500
B69: Alleppey | C69: KL72 | D69: Haveli Backwater Resort | E69: Royal Deluxe | G69: 3200 | H69: 4400 | I69: 5600
B70: Alleppey | C70: KL73 | D70: Haveli Backwater Resort | E70: Royal Grand | G70: 3500 | H70: 4700 | I70: 5900
B71: Alleppey | C71: KL74 | D71: Haveli Backwater Resort | E71: Royal Suite | G71: 4500 | H71: 5700 | I71: 6900
B72: Alleppey | C72: KL75 | D72: Haveli Backwater Resort | E72: Extra Adult passenger | G72: 1000 | H72: 1600 | I72: 2200
B73: Alleppey | C73: KL76 | D73: Haveli Backwater Resort | E73: Child with bed | G73: 800 | H73: 1200 | I73: 1600
B74: Alleppey | C74: KL77 | D74: Haveli Backwater Resort | E74: Child without bed | G74: 500 | H74: 800 | I74: 1100
B75: Alleppey | C75: KL78 | D75: Pagoda Resorts | E75: Deluxe | G75: 2500 | H75: 3600 | I75: 4700
B76: Alleppey | C76: KL79 | D76: Pagoda Resorts | E76: Deluxe Superior | G76: 2800 | H76: 3900 | I76: 5000
B77: Alleppey | C77: KL80 | D77: Pagoda Resorts | E77: Pagoda Cottage | G77: 3300 | H77: 4400 | I77: 5500
B78: Alleppey | C78: KL81 | D78: Pagoda Resorts | E78: Suite | G78: 3600 | H78: 4700 | I78: 5800
...

Sheet Price
A1: Name | B1: Value | D1: Name | E1: Value | G1: Extra passenger | J1: Vehicle | K1: Airport
A2: Venice Iva Residency-Deluxe Room-Double CP | B2: 3900 | D2: Venice Iva Residency-Deluxe Room-Double CP | E2: 3900 | G2: Extra Adult passenger | J2: Sedan 4 Seater | K2: 3200
A3: Venice Iva Residency-Deluxe Room-Double MAP | B3: 5100 | D3: Venice Iva Residency-Deluxe Room-Double MAP | E3: 5100 | G3: Child with bed | J3: Mahindra Xuv Cab | K3: 4500
A4: The Elephant Court-Patio-Double CP | B4: 7200 | D4: The Elephant Court-Patio-Double CP | E4: 7200 | G4: Child without bed | J4: Innova 7 Seater | K4: 6000
A5: The Elephant Court-Patio-Double MAP | B5: 9100 | D5: The Elephant Court-Patio-Double MAP | E5: 9100 | G5: NA | J5: Crysta 7 Seater | K5: 3150
A6: The Elephant Court-Patio-Double AP | B6: 13500 | D6: The Elephant Court-Patio-Double AP | E6: 13500 | J6: Winger 12 Seater | K6: 3800
A7: The Elephant Court-Honeymoon Suite-Double CP | B7: 9500 | D7: The Elephant Court-Honeymoon Suite-Double CP | E7: 9500 | J7: Tempo 17 Seater | K7: 4200
A8: The Elephant Court-Honeymoon Suite-Double MAP | B8: 11400 | D8: The Elephant Court-Honeymoon Suite-Double MAP | E8: 11400 | J8: Tempo 20 Seater | K8: 4700
A9: The Elephant Court-Honeymoon Suite-Double AP | B9: 15800 | D9: The Elephant Court-Honeymoon Suite-Double AP | E9: 15800 | J9: Tempo 25 Seater | K9: 5200
A10: The Elephant Court-Garden Suite-Double CP | B10: 12000 | D10: The Elephant Court-Garden Suite-Double CP | E10: 12000 | J10: Mini Coach 30 Seater | K10: 6200
A11: The Elephant Court-Garden Suite-Double MAP | B11: 13900 | D11: The Elephant Court-Garden Suite-Double MAP | E11: 13900 | J11: Large Coach 40 Seater | K11: 7200
A12: The Elephant Court-Garden Suite-Double AP | B12: 18300 | D12: The Elephant Court-Garden Suite-Double AP | E12: 18300 | J12: NA | K12: 0
A13: The Elephant Court-Pool Studio-Double CP | B13: 14500 | D13: The Elephant Court-Pool Studio-Double CP | E13: 14500
A14: The Elephant Court-Pool Studio-Double MAP | B14: 16400 | D14: The Elephant Court-Pool Studio-Double MAP | E14: 16400
A15: The Elephant Court-Pool Studio-Double AP | B15: 20800 | D15: The Elephant Court-Pool Studio-Double AP | E15: 20800
A16: The Elephant Court-Extra Adult passenger-Double CP | B16: 2000 | D16: The Elephant Court-Extra Adult passenger-Double CP | E16: 2000
A17: The Elephant Court-Extra Adult passenger-Double MAP | B17: 2950 | D17: The Elephant Court-Extra Adult passenger-Double MAP | E17: 2950
A18: The Elephant Court-Extra Adult passenger-Double AP | B18: 3950 | D18: The Elephant Court-Extra Adult passenger-Double AP | E18: 3950
A19: The Elephant Court-Child with bed -Double CP | B19: 1250 | D19: The Elephant Court-Child with bed -Double CP | E19: 1250
A20: The Elephant Court-Child with bed -Double MAP | B20: 1700 | D20: The Elephant Court-Child with bed -Double MAP | E20: 1700
A21: The Elephant Court-Child with bed -Double AP | B21: 2150 | D21: The Elephant Court-Child with bed -Double AP | E21: 2150
A22: The Elephant Court-Child without bed-Double CP | B22: 700 | D22: The Elephant Court-Child without bed-Double CP | E22: 700
A23: The Elephant Court-Child without bed-Double MAP | B23: 1150 | D23: The Elephant Court-Child without bed-Double MAP | E23: 1150
A24: The Elephant Court-Child without bed-Double AP | B24: 1600 | D24: The Elephant Court-Child without bed-Double AP | E24: 1600
... A228: Pagoda Plantation Resort -Valley View Family Room (4 PAX)-Double MAP | B228: 6800 | D228: Pagoda Plantation Resort -Valley View Family Room (4 PAX)-Double MAP | E228: 6800
A229: Pagoda Plantation Resort -Valley View Family Room (4 PAX)-Triple EP | D229: Pagoda Plantation Resort -Valley View Family Room (4 PAX)-Triple EP
A230: Pagoda Plantation Resort -Tea Valley Deluxe-Double CP | B230: 5000 | D230: Pagoda Plantation Resort -Tea Valley Deluxe-Double CP | E230: 5000
A231: Pagoda Plantation Resort -Tea Valley Deluxe-Double MAP | B231: 6000 | D231: Pagoda Plantation Resort -Tea Valley Deluxe-Double MAP | E231: 6000
A232: Pagoda Plantation Resort -Tea Valley Deluxe-Triple EP | D232: Pagoda Plantation Resort -Tea Valley Deluxe-Triple EP
A233: Pagoda Plantation Resort -Tea Valley Premium-Double CP | B233: 5500 | D233: Pagoda Plantation Resort -Tea Valley Premium-Double CP | E233: 5500
A234: Pagoda Plantation Resort -Tea Valley Premium-Double MAP | B234: 6500 | D234: Pagoda Plantation Resort -Tea Valley Premium-Double MAP | E234: 6500
A235: Pagoda Plantation Resort -Tea Valley Premium-Triple EP | D235: Pagoda Plantation Resort -Tea Valley Premium-Triple EP
A236: Pagoda Plantation Resort -Extra Adult passenger-Double CP | B236: 900 | D236: Pagoda Plantation Resort -Extra Adult passenger-Double CP | E236: 900
A237: Pagoda Plantation Resort -Extra Adult passenger-Double MAP | B237: 1400 | D237: Pagoda Plantation Resort -Extra Adult passenger-Double MAP | E237: 1400
A238: Pagoda Plantation Resort -Child with bed -Double CP | B238: 600 | D238: Pagoda Plantation Resort -Child with bed -Double CP | E238: 600
A239: Pagoda Plantation Resort -Child with bed -Double MAP | B239: 900 | D239: Pagoda Plantation Resort -Child with bed -Double MAP | E239: 900
A240: Pagoda Plantation Resort -Child without bed-Double CP | B240: 400 | D240: Pagoda Plantation Resort -Child without bed-Double CP | E240: 400
A241: Pagoda Plantation Resort -Child without bed-Double MAP | B241: 700 | D241: Pagoda Plantation Resort -Child without bed-Double MAP | E241: 700
A242: Pagoda Plantation Resort -Child without bed-Triple EP | D242: Pagoda Plantation Resort -Child without bed-Triple EP
A243: The Breeze Resort -Valley View Room (With Balcony)-Double CP | B243: 3750 | D243: The Breeze Resort -Valley View Room (With Balcony)-Double CP | E243: 3750
...

Sheet ActivitiesMaster
C1: Name of Activity | D1: Description | E1: Price
C2: Honeymoon Inclusions | D2: ABC
C3: Candle Lit Dinner
C14: Vehicle | D14: Airport
C15: Mahindra Xuv Cab | D15: 4500
C16: Innova 7 Seater | D16: 6000
C25: Taxi Shim Meghalaya | D25: 70056 76675

Sheet Day Wise Exursion
A1: Day No. | B1: Title | C1: Description
A2: =IF(B2="","", "Day " & ROW(A2)-1) -> Day 1 | B2: Arrival at Cochin & Transfer to Munnar + Munnar Sightseeing | C2: Upon arrival in Cochin, proceed to Munnar for a day of sightseeing. Start with a visit to Mattupetty Dam (additional ticket fee applies), a concrete gravity dam nestled in the mountains. Mattupetty offers a captivating blend of natural beauty, featuring sprawling tea plantations, rolling grasslands, and lush Shola forests. These forests are perfect for trekking and serve as a habitat for a wide variety of birds. Later visit Kundala Dam (ticket price extra), the famous Neela Kurunji flowers which bloom once in twelve years, bloom in the hills and valleys around Kundala lake. Enroute visit Echo Point & Pothamedu View Point. Echo Point always has a greenish look as it is covered with abundant green sceneries. View Point is perfect to enjoy the spectacular beauty of the coffee, tea & cardamom plantations. They are an adventurous destination, which will be a perfect choice for those who love to have a nature walk or trekking. Overnight stay at Hotel.
A3: =IF(B3="","", "Day " & ROW(A3)-1) -> Day 2 | B3: Arrival at Cochin - Athirappilly Falls - Munnar | C3: On arrival at Cochin, proceed to Munnar via Athirappilly falls, the most famous waterfalls of Kerala. The 80 ft high and 330 ft wide Athirapally falls is a majestic waterfall that is right in front of the Sholayar ranges and is often referred to as the "Niagara Falls of India". Just 5 km from this fall is another majestic waterfall - Vazhachal. After spending some time at the waterfalls, proceed towards Munnar. Situated at 1,600m above sea level with unending expanse of tea plantations - pristine valleys and mountains, you’re often up above the clouds watching veils of mist clinging to the mountain tops. Overnight stay at Hotel.
A4: =IF(B4="","", "Day " & ROW(A4)-1) -> Day 3 | B4: Munnar Full Day Sightseeing Tour | C4: After breakfast proceed for sightseeing of Munnar. Visit Eravikulam National Park (ticket price extra) Closed for Jan 2025 till March 2025 & Mattupetty Dam (ticket price extra), a storage concrete gravity dam built in the mountains. Mattupetty offers many fascinating sights to relish. Besides the tea plantations & the rolling grasslands, the Shola forests in and around Mattupetty are ideal for trekking and are habitat to a variety of birds. Later visit Kundala Dam (ticket price extra), the famous Neela Kurunji flowers which bloom once in twelve years, bloom in the hills and valleys around Kundala lake. Enroute visit Echo Point & Pothamedu View Point. Echo Point always has a greenish look as it is covered with abundant green sceneries. View Point is perfect to enjoy the spectacular beauty of the coffee, tea & cardamom plantations. They are an adventurous destination, which will be a perfect choice for those who love to have a nature walk or trekking. Overnight stay at Hotel.
A5: =IF(B5="","", "Day " & ROW(A5)-1) -> Day 4 | B5: Munnar Dream Land Spices Park | C5: Enjoy your breakfast today before we head out. We’re going on a trip to Dream Land Spices Park at an extra cost for entry and rides. There’s so much to do and explore here where you can go for challenging Tyre Climbing or get drenched at the Water Park. Try out the Archery and Camel Ride, have fun at the Trampoline or bond with your family with some off-road cycling and city scooter. There’s something for everyone here! We’re going to head back to the hotel in Munnar for our overnight stay after this.
A6: =IF(B6="","", "Day " & ROW(A6)-1) -> Day 5 | B6: Transfer from Munnar to Thekkady - (85 Kms - Approx 3 Hrs) | C6: After breakfast, check out from hotel & proceed to Thekkady. Thekkady is considered as a heaven for natural spices. The Periyar forests of Thekkady is one of the finest wildlife reserves in India. Periyar encompasses 777 sq km & a 26-sq-km artificial lake. Check-in at hotel & later head out for sightseeing to visit the Periyar Wildlife Sanctuary (ticket price extra), it is home to herds of wild Elephants, Sambar, Tigers, Gaur, Lion-tailed Macaques, Nilgiri Langurs & more. The place can sometimes feel a bit like Disneyland-in-the-Ghats, but its mountain scenery & jungle walks make for an enjoyable visit. Evening enjoy the boat cruise in the lake (at additional cost) to spot wild animals. Overnight stay at Hotel.
A7: =IF(B7="","", "Day " & ROW(A7)-1) -> Day 6 | B7: Transfer from Thekkady to Alleppey - (135 Kms - Approx 4 Hrs) | C7: After breakfast, check out from hotel and proceed to Alleppey which has an immense natural beauty and is also known as the “Venice of the East”. It is famous for backwater cruising and boat race. Check into your hotel/houseboat & cruise (if staying in houseboat) through the Narrow Canal amidst the Paddy Fields, Coconut Lagoons and Coir Villages in Alleppey. Overnight stay in Alleppey.
A8: =IF(B8="","", "Day " & ROW(A8)-1) -> Day 7 | B8: Transfer from Alleppey to Kovalam (160 Kms - Approx 4.5 Hrs) | C8: After breakfast, check out from hotel & proceed to Kovalam. Kovalam is an internationally renowned beach destination with three adjacent crescent beaches & also known as the "Paradise of the South". On arrival check-in at the hotel & relax for a while amidst the comforts of your room. By evening explore on your own to see how the everlasting sea touches the everlasting sky. Kovalam is the place where one can see the golden sand at the day time & silver sand in the night, with high rock promontory & a calm bay of blue waters, this beach paradise creates a unique aquarelle on moonlight nights. Overnight stay at Hotel.
A9: =IF(B9="","", "Day " & ROW(A9)-1) -> Day 8 | B9: Transfer from Alleppey to Kovalam (160 Kms - Approx 4.5 Hrs) Via Poovar | C9: After breakfast check out from hotel & proceed to Trivandrum, city of the Holy Ananth which is named after Ananthan, the cosmic serpent with a thousand heads. Visit Sri Padmanabhaswamy Temple (260 yrs old) - the most religious icon of the city built by the Travancore Royal family, here the deity Padmanabha reclines on the sacred serpent & is made from over 10,000 salagramam (sacred stones) that were transported from Nepal by elephant. Poovar is one among the natural wonders where the Lake, River, Sea and Beach meet the land. A rare find in Kerala. Poovar is basically a fishing village and the only way to reach Poovar is through water, it is known for its pristine and virginal beauty, Poovar Beach is haunted by those who love solitude. Later proceed to Kovalam. Kovalam is an internationally renowned beach destination with three adjacent crescent beaches & also known as the "Paradise of the South". On arrival check in at the hotel & relax for a while amidst the comforts of your room. By evening explore on your own to see how the everlasting sea touches the everlasting sky. Kovalam is the place where one can see the golden sand at the day time & silver sand in the night, with high rock promontory & a calm bay of blue waters, this beach paradise creates a unique aquarelle on moonlight nights. Overnight stay at Hotel.
A10: =IF(B10="","", "Day " & ROW(A10)-1) -> Day 9 | B10: Transfer from Alleppey to Kovalam (160 Kms - Approx 4.5 Hrs) With Sri Padmanabhaswamy Temple | C10: After breakfast check out from hotel & proceed to Trivandrum, city of the Holy Ananth which is named after Ananthan, the cosmic serpent with a thousand heads. Visit Sri Padmanabhaswamy Temple (260 yrs old) - the most religious icon of the city built by the Travancore Royal family, here the deity Padmanabha reclines on the sacred serpent & is made from over 10,000 salagramam (sacred stones) that were transported from Nepal by elephant. Later proceed to Kovalam. Kovalam is an internationally renowned beach destination with three adjacent crescent beaches & also known as the "Paradise of the South". On arrival check in at the hotel & relax for a while amidst the comforts of your room. By evening explore on your own to see how the everlasting sea touches the everlasting sky. Kovalam is the place where one can see the golden sand at the day time & silver sand in the night, with high rock promontory & a calm bay of blue waters, this beach paradise creates a unique aquarelle on moonlight nights. Overnight stay at Hotel.
A11: =IF(B11="","", "Day " & ROW(A11)-1) -> Day 10 | B11: Transfer from Alleppey to Kovalam enroute Jatayu Earth Centre | C11: After breakfast in the morning, proceed for Jatayu earth's center located at a small village called Chadayamangalam in Kollam (around 50 kms from Trivandrum). Its assumed that this is the place where – Jatayu, a demi-god of Hindu epic "Ramayana" having the form of a vulture, fought with Ravana - multi headed demon king of Lanka (now Sri Lanka) to prevent kidnapping of Goddess Sita, and got slain off one of his wing. The giant concrete statue of Jatayu is built on a mighty rock named Jatayupara (para means rock in Malayalam). The colossal statue is 200 feet long, 150 feet wide and 70 feet making is the largest functional bird sculpture in the world. You can take a cable car ride (on supplementary cost) to visit the Jatayu statue, audio visual museum and mini theatre. Cable car can be booked online in advance. Jatayu earth's center is spread across four hills in Chadayamangalam. The Jatayu Rock Hill represents the safety of women and their honour. The Adventure Rock Hill offers many adventure activities and nature walk. Adventure activities (all on supplementary cost) include paintball, rifle shooting, chimney climbing, rappelling, bouldering, etc. At Elephant Rock Hill, you can enjoy an overnight stay here in tented camps. The spot offers zip-lining, campfire, live music and kitchen, etc. The fourth hill, The Kitchen Rock Hill, provides a ten-day Siddha rejuvenation package. Then proceed to Kovalam. Kovalam is an internationally renowned beach destination with three adjacent crescent beaches & also known as the "Paradise of the South". On arrival check-in at the hotel & relax for a while amidst the comforts of your room. By evening explore on your own to see how the everlasting sea touches the everlasting sky. Kovalam is the place where one can see the golden sand at the day time & silver sand in the night, with high rock promontory & a calm bay of blue waters, this beach paradise creates a unique aquarelle on moonlight nights. Overnight stay at Hotel.
A12: =IF(B12="","", "Day " & ROW(A12)-1) -> Day 11 | B12: Sightseeing of Trivandrum & Return to Kovalam (16 Kms - Approx 30 Mins) | C12: After breakfast proceed for sightseeing of Trivandrum, city of the Holy Ananth which is named after Ananthan, the cosmic serpent with a thousand heads. Visit Sri Padmanabhaswamy Temple (260 yrs old) - the most religious icon of the city built by the Travancore Royal family, here the deity Padmanabha reclines on the sacred serpent & is made from over 10,000 salagramam (sacred stones) that were transported from Nepal by elephant. Secondly, visit Puthe Maliga Palace Museum (ticket price extra) - a 200 year old palace which has carved wooden ceilings, marble sculptures & imported Belgian glass. Inside you'll find Kathakali images, an armoury, portraits of maharajas, ornate thrones & other artefacts. Later proceed to Veli Tourist Village, a beautiful & popular picnic spot well-known because of its serenity, the Lake that meets the Arabian Sea. The main attraction of Veli Tourist Village is a floating bridge that has been erected at this place. The place also has a floating restaurant that gives you an amazing array of food products which might match your taste buds. By evening proceed to Shankumugham Beach, the beach is well known for its breathtaking sunset view which is such memorable moment whose beauty will refresh your mind. The beautiful sculpture of a mermaid is a major attraction here, this giant statue is more than 35m long. Later return to Kovalam. Overnight stay at the Hotel. less Sree Padmanabhaswamy Temple, Shanghumukham Beach, Veli Tourist Village, Kuthiramalika Palace Museum are also covered on Day 7 (Transfer to Trivandrum + Sightseeing of Trivandrum + Departure from Trivandrum); Kuthiramalika Palace Museum - Closed
A13: =IF(B13="","", "Day " & ROW(A13)-1) -> Day 12 | B13: Day Sightseeing of Kanyakumari | C13: After breakfast, embark on a scenic drive to Kanyakumari, a town enveloped by majestic hills and scenic sea-shores, adorned with coconut trees and lush paddy fields. En route, make a stop at Suchindram, a sacred site situated along the banks of the river Pazhayar. In Kanyakumari, pay a visit to the Vivekananda Rock Memorial (entrance fee required), a revered monument believed to be the site where Goddess Kanyakumari undertook her Tapas. Next, explore the Thiruvalluvar Statue, a monumental tribute to Thiruvalluvar. The pedestal of the statue stands at 38 feet tall, while the statue itself towers at 95 feet, making for a grand total of 133 feet for the entire sculpture. In the evening, return to Kovalam for an overnight stay at your hotel.
... A17: =IF(B17="","", "Day " & ROW(A17)-1) -> Day 16 | B17: Transfer to Trivandrum + Sightseeing of Trivandrum + Departure from Trivandrum | C17: After breakfast, proceed for sightseeing of Trivandrum. Visit Sri Padmanabhaswamy Temple (260 yrs old) - the most religious icon of the city built by the Travancore Royal family, here the deity Padmanabha reclines on the sacred serpent & is made from over 10,000 salagramam (sacred stones) that were transported from Nepal by elephant. Secondly, visit Puthe Maliga Palace Museum (ticket price extra) - a 200 year old palace which has carved wooden ceilings, marble sculptures & imported Belgian glass. Inside you'll find Kathakali images, an armoury, portraits of maharajas, ornate thrones & other artefacts. Later proceed to Veli Tourist Village, a beautiful & popular picnic spot well-known because of its serenity, the Lake that meets the Arabian Sea. The main attraction of Veli Tourist Village is a floating bridge that has been erected at this place. The place also has a floating restaurant that gives you an amazing array of food products which might match your taste buds. By evening proceed to Shankumugham Beach, the beach is well known for its breathtaking sunset view which is such memorable moment whose beauty will refresh your mind. The beautiful sculpture of a mermaid is a major attraction here, this giant statue is more than 35m long. Later transfer to Trivandrum airport/railway station for departure, back to home with beautiful memories of God's Own Country
A18: =IF(B18="","", "Day " & ROW(A18)-1)
A19: =IF(B19="","", "Day " & ROW(A19)-1)
A20: =IF(B20="","", "Day " & ROW(A20)-1)
A21: =IF(B21="","", "Day " & ROW(A21)-1)
A22: =IF(B22="","", "Day " & ROW(A22)-1)
A23: =IF(B23="","", "Day " & ROW(A23)-1)
A24: =IF(B24="","", "Day " & ROW(A24)-1)
A25: =IF(B25="","", "Day " & ROW(A25)-1)
A26: =IF(B26="","", "Day " & ROW(A26)-1)
A27: =IF(B27="","", "Day " & ROW(A27)-1)
A28: =IF(B28="","", "Day " & ROW(A28)-1)
A29: =IF(B29="","", "Day " & ROW(A29)-1)
... A32: =IF(B32="","", "Day " & ROW(A32)-1)

Sheet Sheet2
B1: City
B2: {=_xlfn.UNIQUE(RAW[[Destination ]])} -> Alleppey | C2: INDEX(Sheet1!$B$3:$D$7,0,MATCH(Sheet1!$B$11,Heading,0))
B3: Thekkady
B4: Kovalam
B5: Thiruvananthapuram
B6: Munnar
B7: Varkala
B8: Kochi
A12: City | B12: Hotecode | C12: Hotel Name | H12: {=TRANSPOSE($C$13:$C$790)} -> Venice Iva Residency | I12: The Elephant Court | J12: The Elephant Court | K12: The Elephant Court | L12: The Elephant Court | M12: The Elephant Court | N12: The Elephant Court | O12: The Elephant Court | P12: Peppervine | Q12: Peppervine | R12: Peppervine | S12: Peppervine | T12: Peppervine | U12: Peppervine | V12: Uday Samudra Beach Hotel | W12: Uday Samudra Leisure Beach Hotel | X12: Uday Samudra Leisure Beach Hotel | Y12: Uday Samudra Leisure Beach Hotel | Z12: Uday Samudra Leisure Beach Hotel | AA12: Uday Samudra Leisure Beach Hotel | AB12: Uday Samudra Leisure Beach Hotel | AC12: Uday Samudra Leisure Beach Hotel | AD12: Uday Samudra Leisure Beach Hotel | AE12: Uday Samudra Leisure Beach Hotel | AF12: Uday Samudra Leisure Beach Hotel | AG12: Uday Samudra Leisure Beach Hotel | AH12: The Byke Heritage - Puja Samudra | AI12: The Byke Heritage - Puja Samudra | AJ12: Uday Backwater Resort | AK12: Uday Backwater Resort | AL12: Uday Backwater Resort | AM12: Uday Backwater Resort | AN12: Uday Backwater Resort | AO12: Uday Backwater Resort | AP12: Uday Backwater Resort | AQ12: Uday Backwater Resort | AR12: Uday Backwater Resort | AS12: Uday Suites, The Airport Hotel | AT12: Uday Suites, The Airport Hotel | AU12: Uday Suites, The Airport Hotel | AV12: Uday Suites, The Airport Hotel | AW12: Uday Suites, The Airport Hotel | AX12: Uday Suites, The Airport Hotel | AY12: Uday Suites, The Airport Hotel | AZ12: Uday Suites, The Airport Hotel | BA12: Tea castle resort | BB12: Tea castle resort | BC12: Tea castle resort | BD12: Tea castle resort | BE12: Tea castle resort | BF12: Tea castle resort | BG12: The Breeze Resort | BH12: The Breeze Resort | BI12: The Whispering Meadows | BJ12: The Whispering Meadows | BK12: Blossom Hill Resort | BL12: Blossom Hill Resort | BM12: Venice Iva Residency | BN12: Venice Iva Residency | BO12: Seven Springs Plantation Resort | BP12: Seven Springs Plantation Resort | BQ12: Seven Springs Plantation Resort | BR12: Seven Springs Plantation Resort | BS12: Seven Springs Plantation Resort | BT12: Casino Houseboats | BU12: Casino Houseboats | BV12: Haveli Backwater Resort | BW12: Haveli Backwater Resort | BX12: Haveli Backwater Resort | BY12: Haveli Backwater Resort | BZ12: Haveli Backwater Resort | CA12: Haveli Backwater Resort | CB12: Pagoda Resorts | CC12: Pagoda Resorts | CD12: Pagoda Resorts | CE12: Pagoda Resorts | CF12: Pagoda Resorts | CG12: Pagoda Resorts | CH12: Pagoda Resorts | CI12: Pagoda Plantation Resort | CJ12: Pagoda Plantation Resort | CK12: Pagoda Plantation Resort | CL12: Pagoda Plantation Resort | CM12: Pagoda Plantation Resort | CN12: Pagoda Plantation Resort | CO12: Pagoda Plantation Resort | CP12: Pagoda Plantation Resort | CQ12: Pagoda Plantation Resort | CR12: The Breeze Resort | CS12: Jungle Park Resort | CT12: Jungle Park Resort | CU12: Jungle Park Resort | CV12: Jungle Park Resort | CW12: Jungle Park Resort | CX12: Jungle Park Resort | CY12: Jungle Park Resort | CZ12: Jungle Park Resort | DA12: Blossom Hill Resort | DB12: Symphony Houseboats | DC12: Jeevan Beach Resort | DD12: Jeevan Beach Resort | DE12: Jeevan Beach Resort | DF12: Jeevan Beach Resort | DG12: Jeevan Beach Resort | DH12: Jeevan Beach Resort | DI12: Sunview Beach Resort & Spa by Citrine | DJ12: Sunview Beach Resort & Spa by Citrine | DK12: Sunview Beach Resort & Spa by Citrine | DL12: Sunview Beach Resort & Spa by Citrine | DM12: Sunview Beach Resort & Spa by Citrine | DN12: Sunview Beach Resort & Spa by Citrine | DO12: Sunview Beach Resort & Spa by Citrine | DP12: Venice Iva Residency | DQ12: Venice Iva Residency | DR12: Venice Iva Residency | DS12: Sprise Munnar Resort & Spa | DT12: Sprise Munnar Resort & Spa | DU12: Sprise Munnar Resort & Spa | DV12: Sprise Munnar Resort & Spa | DW12: Sprise Munnar Resort & Spa | DX12: Sprise Munnar Resort & Spa | DY12: Sprise Munnar Resort & Spa | DZ12: Broad Bean Hotel | EA12: Broad Bean Hotel | EB12: Broad Bean Hotel | EC12: Broad Bean Hotel | ED12: Broad Bean Hotel | EE12: Broad Bean Hotel | EF12: Broad Bean Hotel | EG12: Broad Bean Hotel | EH12: The Breeze Resort | EI12: The Breeze Resort | EJ12: Jeevan Beach Resort | EK12: Jeevan Beach Resort | EL12: Jeevan Beach Resort | EM12: Blossom Hill Resort | EN12: Blossom Hill Resort | EO12: Lagoona Beach Resort | EP12: Lagoona Beach Resort | EQ12: Lagoona Beach Resort | ER12: Lagoona Beach Resort | ES12: Lagoona Beach Resort | ET12: Lagoona Beach Resort | EU12: Lagoona Beach Resort | EV12: Lagoona Beach Resort | EW12: Lagoona Beach Resort | EX12: The Whispering Meadows | EY12: The Whispering Meadows | EZ12: The Whispering Meadows | FA12: Napier Heritage Fort | FB12: Napier Heritage Fort | FC12: Napier Heritage Fort | FD12: Napier Heritage Fort | FE12: Napier Heritage Fort | FF12: Napier Heritage Fort | FG12: Napier Heritage Fort | FH12: Napier Heritage Fort | FI12: Napier Heritage Fort | FJ12: Napier Heritage Fort | FK12: Trium Resort & Houseboats | FL12: Trium Resort & Houseboats | FM12: Trium Resort & Houseboats | FN12: Trium Resort & Houseboats | FO12: Trium Resort & Houseboats | FP12: Trium Resort & Houseboats | FQ12: Trium Deluxe Houseboats | FR12: Trium Deluxe Houseboats | FS12: Trium Preimum Houseboats | FT12: Trium Preimum Houseboats | FU12: Ocean Bay Ayurvedic Beach Resort | FV12: Ocean Bay Ayurvedic Beach Resort | FW12: Ocean Bay Ayurvedic Beach Resort | FX12: Ocean Bay Ayurvedic Beach Resort | FY12: Ocean Bay Ayurvedic Beach Resort | FZ12: Aadisaktthi Resort | GA12: Aadisaktthi Resort | GB12: Aadisaktthi Resort | GC12: Aadisaktthi Resort | GD12: Aadisaktthi Resort | GE12: Aadisaktthi Resort | GF12: Aadisaktthi Resort | GG12: Aadisaktthi Resort | GH12: Aadisaktthi Resort | GI12: Miraaya Sundara Island Villa | GJ12: Miraaya Sundara Island Villa | GK12: Miraaya Sundara Island Villa | GL12: Miraaya Sundara Island Villa | GM12: Miraaya Sundara Island Villa
A13: =IF(B12="","",_xlfn.XLOOKUP(B13,'Raw'!C:C,'Raw'!B:B)) -> Alleppey | B13: {=_xlfn.UNIQUE(RAW[Hotel Code])} -> KL1 | C13: =IF(B13="","",VLOOKUP(B13,RAW[[Hotel Code]:[Hotel / Resort Name ]],2,0)) -> Venice Iva Residency | H13: {=IF(H12="","",_xlfn._xlws.FILTER(RAW[[#All],[Room Type]],RAW[[#All],[Hotel / Resort Name ]]=Sheet2!H$12))} -> Deluxe Room | I13: {=IF(I12="","",_xlfn._xlws.FILTER(RAW[[#All],[Room Type]],RAW[[#All],[Hotel / Resort Name ]]=Sheet2!I$12))} -> Patio | J13: {=IF(J12="","",_xlfn._xlws.FILTER(RAW[[#All],[Room Type]],RAW[[#All],[Hotel / Resort Name ]]=Sheet2!J$12))} -> Patio | K13: {=IF(K12="","",_xlfn._xlws.FILTER(RAW[[#All],[Room Type]],RAW[[#All],[Hotel / Resort Name ]]=Sheet2!K$12))} -> Patio | L13: {=IF(L12="","",_xlfn._xlws.FILTER(RAW[[#All],[Room Type]],RAW[[#All],[Hotel / Resort Name ]]=Sheet2!L$12))} -> Patio | M13: {=IF(M12="","",_xlfn._xlws.FILTER(RAW[[#All],[Room Type]],RAW[[#All],[Hotel / Resort Name ]]=Sheet2!M$12))} -> Patio | N13: {=IF(N12="","",_xlfn._xlws.FILTER(RAW[[#All],[Room Type]],RAW[[#All],[Hotel / Resort Name ]]=Sheet2!N$12))} -> Patio | O13: {=IF(O12="","",_xlfn._xlws.FILTER(RAW[[#All],[Room Type]],RAW[[#All],[Hotel / Resort Name ]]=Sheet2!O$12))} -> Patio | ... BR13: {=IF(BR12="","",_xlfn._xlws.FILTER(RAW[[#All],[Room Type]],RAW[[#All],[Hotel / Resort Name ]]=Sheet2!BR$12))} -> Deluxe Room | BS13: {=IF(BS$12<>"",_xlfn.UNIQUE(_xlfn._xlws.FILTER(RAW[[#All],[Room Type]],RAW[[#All],[Hotel / Resort Name ]]=Sheet2!BS$12)),"")} -> Deluxe Room | BT13: {=IF(BT$12<>"",_xlfn.UNIQUE(_xlfn._xlws.FILTER(RAW[[#All],[Room Type]],RAW[[#All],[Hotel / Resort Name ]]=Sheet2!BT$12)),"")} -> Standard | BU13: {=IF(BU$12<>"",_xlfn.UNIQUE(_xlfn._xlws.FILTER(RAW[[#All],[Room Type]],RAW[[#All],[Hotel / Resort Name ]]=Sheet2!BU$12)),"")} -> Standard | BV13: {=IF(BV$12<>"",_xlfn.UNIQUE(_xlfn._xlws.FILTER(RAW[[#All],[Room Type]],RAW[[#All],[Hotel / Resort Name ]]=Sheet2!BV$12)),"")} -> Royal Deluxe | BW13: {=IF(BW$12<>"",_xlfn.UNIQUE(_xlfn._xlws.FILTER(RAW[[#All],[Room Type]],RAW[[#All],[Hotel / Resort Name ]]=Sheet2!BW$12)),"")} -> Royal Deluxe | BX13: {=IF(BX$12<>"",_xlfn.UNIQUE(_xlfn._xlws.FILTER(RAW[[#All],[Room Type]],RAW[[#All],[Hotel / Resort Name ]]=Sheet2!BX$12)),"")} -> Royal Deluxe | BY13: {=IF(BY$12<>"",_xlfn.UNIQUE(_xlfn._xlws.FILTER(RAW[[#All],[Room Type]],RAW[[#All],[Hotel / Resort Name ]]=Sheet2!BY$12)),"")} -> Royal Deluxe | BZ13: {=IF(BZ$12<>"",_xlfn.UNIQUE(_xlfn._xlws.FILTER(RAW[[#All],[Room Type]],RAW[[#All],[Hotel / Resort Name ]]=Sheet2!BZ$12)),"")} -> Royal Deluxe | ... ADE13: {=IF(ADE$12<>"",_xlfn.UNIQUE(_xlfn._xlws.FILTER(RAW[[#All],[Room Type]],RAW[[#All],[Hotel / Resort Name ]]=Sheet2!ADE$12)),"")}
A14: =IF(B13="","",_xlfn.XLOOKUP(B14,'Raw'!C:C,'Raw'!B:B)) -> Thekkady | B14: KL2 | C14: =IF(B14="","",VLOOKUP(B14,RAW[[Hotel Code]:[Hotel / Resort Name ]],2,0)) -> The Elephant Court | H14: Quadruple Bed Room (04 pax) | I14: Honeymoon Suite | J14: Honeymoon Suite | K14: Honeymoon Suite | L14: Honeymoon Suite | M14: Honeymoon Suite | N14: Honeymoon Suite | O14: Honeymoon Suite | P14: Suite Room | Q14: Suite Room | R14: Suite Room | S14: Suite Room | T14: Suite Room | U14: Suite Room | W14: Pool view Room | X14: Pool view Room | Y14: Pool view Room | Z14: Pool view Room | AA14: Pool view Room | AB14: Pool view Room | AC14: Pool view Room | AD14: Pool view Room | AE14: Pool view Room | AF14: Pool view Room | AG14: Pool view Room | AH14: Super Deluxe | AI14: Super Deluxe | AJ14: Lake View Elite Rooms | AK14: Lake View Elite Rooms | AL14: Lake View Elite Rooms | AM14: Lake View Elite Rooms | AN14: Lake View Elite Rooms | AO14: Lake View Elite Rooms | AP14: Lake View Elite Rooms | AQ14: Lake View Elite Rooms | AR14: Lake View Elite Rooms | AS14: Ixora | AT14: Ixora | AU14: Ixora | AV14: Ixora | AW14: Ixora | AX14: Ixora | AY14: Ixora | AZ14: Ixora | BA14: Deluxe Room | BB14: Deluxe Room | BC14: Deluxe Room | BD14: Deluxe Room | BE14: Deluxe Room | BF14: Deluxe Room | BG14: Extra Adult passenger | BH14: Extra Adult passenger | BI14: Extra Adult passenger | BJ14: Extra Adult passenger | BK14: Extra Adult passenger | BL14: Extra Adult passenger | BM14: Quadruple Bed Room (04 pax) | BN14: Quadruple Bed Room (04 pax) | BO14: Super Deluxe Room | BP14: Super Deluxe Room | BQ14: Super Deluxe Room | BR14: Super Deluxe Room | BS14: Super Deluxe Room | BT14: Preimum | BU14: Preimum | BV14: Royal Grand | BW14: Royal Grand | BX14: Royal Grand | BY14: Royal Grand | BZ14: Royal Grand | CA14: Royal Grand | CB14: Deluxe Superior | CC14: Deluxe Superior | CD14: Deluxe Superior | CE14: Deluxe Superior | CF14: Deluxe Superior | CG14: Deluxe Superior | CH14: Deluxe Superior | CI14: Hill Top Deluxe | CJ14: Hill Top Deluxe | CK14: Hill Top Deluxe | CL14: Hill Top Deluxe | CM14: Hill Top Deluxe | CN14: Hill Top Deluxe | CO14: Hill Top Deluxe | CP14: Hill Top Deluxe | CQ14: Hill Top Deluxe | CR14: Extra Adult passenger | CS14: Jungle View Venus (A/c) | CT14: Jungle View Venus (A/c) | CU14: Jungle View Venus (A/c) | CV14: Jungle View Venus (A/c) | CW14: Jungle View Venus (A/c) | CX14: Jungle View Venus (A/c) | CY14: Jungle View Venus (A/c) | CZ14: Jungle View Venus (A/c) | DA14: Extra Adult passenger | DC14: Sea Shore (Partial Sea View over the Pool) | DD14: Sea Shore (Partial Sea View over the Pool) | DE14: Sea Shore (Partial Sea View over the Pool) | DF14: Sea Shore (Partial Sea View over the Pool) | DG14: Sea Shore (Partial Sea View over the Pool) | DH14: Sea Shore (Partial Sea View over the Pool) | DI14: Pool View | DJ14: Pool View | DK14: Pool View | DL14: Pool View | DM14: Pool View | DN14: Pool View | DO14: Pool View | DP14: Quadruple Bed Room (04 pax) | DQ14: Quadruple Bed Room (04 pax) | DR14: Quadruple Bed Room (04 pax) | DS14: Majestic Ponmudi Dam View | DT14: Majestic Ponmudi Dam View | DU14: Majestic Ponmudi Dam View | DV14: Majestic Ponmudi Dam View | DW14: Majestic Ponmudi Dam View | DX14: Majestic Ponmudi Dam View | DY14: Majestic Ponmudi Dam View | DZ14: Deluxe Room | EA14: Deluxe Room | EB14: Deluxe Room | EC14: Deluxe Room | ED14: Deluxe Room | EE14: Deluxe Room | EF14: Deluxe Room | EG14: Deluxe Room | EH14: Extra Adult passenger | EI14: Extra Adult passenger | EJ14: Sea Shore (Partial Sea View over the Pool) | EK14: Sea Shore (Partial Sea View over the Pool) | EL14: Sea Shore (Partial Sea View over the Pool) | EM14: Extra Adult passenger | EN14: Extra Adult passenger | EO14: Lagoona Standard Non-Sea View | EP14: Lagoona Standard Non-Sea View | EQ14: Lagoona Standard Non-Sea View | ER14: Lagoona Standard Non-Sea View | ES14: Lagoona Standard Non-Sea View | ET14: Lagoona Standard Non-Sea View | EU14: Lagoona Standard Non-Sea View | EV14: Lagoona Standard Non-Sea View | EW14: Lagoona Standard Non-Sea View | EX14: Extra Adult passenger | EY14: Extra Adult passenger | EZ14: Extra Adult passenger | FA14: Executive Room | FB14: Executive Room | FC14: Executive Room | FD14: Executive Room | FE14: Executive Room | FF14: Executive Room | FG14: Executive Room | FH14: Executive Room | FI14: Executive Room | FJ14: Executive Room | FK14: Standard Room AC | FL14: Standard Room AC | FM14: Standard Room AC | FN14: Standard Room AC | FO14: Standard Room AC | FP14: Standard Room AC | FQ14: Day Nigt Cruise 12PM-9AM | FR14: Day Nigt Cruise 12PM-9AM | FS14: Day Nigt Cruise 12PM-9AM | FT14: Day Nigt Cruise 12PM-9AM | FU14: DLX AC DBL | FV14: DLX AC DBL | FW14: DLX AC DBL | FX14: DLX AC DBL | FY14: DLX AC DBL | FZ14: Club Deluxe Garden view | GA14: Club Deluxe Garden view | GB14: Club Deluxe Garden view | GC14: Club Deluxe Garden view | GD14: Club Deluxe Garden view | GE14: Club Deluxe Garden view | GF14: Club Deluxe Garden view | GG14: Club Deluxe Garden view | GH14: Club Deluxe Garden view | GI14: Jacuzzi Suite Villa | GJ14: Jacuzzi Suite Villa | GK14: Jacuzzi Suite Villa | GL14: Jacuzzi Suite Villa | GM14: Jacuzzi Suite Villa
